Workbook
Name Slicer_Representative: #N/A

Sheet Sheet3
A1: Data returned for call count, Columbus (First 1000 rows).
A3: calls[Call number] | B3: calls[Customer ID] | C3: calls[Duration] | D3: calls[Representative] | E3: calls[Date of Call] | F3: calls[Purchase Amount] | G3: calls[Satisfaction Rating] | H3: calls[FY] | I3: calls[Day of week] | J3: calls[Duration Bucket] | K3: calls[Rating rounded] | L3: calls[Date of Call (Month)] | M3: calls[Date of Call (Month Index)]
A4: Call_7273 | B4: C0005 | C4: 68 | D4: R02 | E4: 44927 | F4: 66 | G4: 4.7 | H4: 2023 | I4: Sunday | J4: 1 to 2 hours | K4: 5 | L4: Jan | M4: 1
A5: Call_7274 | B5: C0014 | C5: 119 | D5: R02 | E5: 44927 | F5: 22 | G5: 2.9 | H5: 2023 | I5: Sunday | J5: 1 to 2 hours | K5: 3 | L5: Jan | M5: 1
A6: Call_7279 | B6: C0005 | C6: 31 | D6: R02 | E6: 44929 | F6: 135 | G6: 3.6 | H6: 2023 | I6: Tuesday | J6: 30 to 60 mins | K6: 4 | L6: Jan | M6: 1
A7: Call_7288 | B7: C0009 | C7: 28 | D7: R03 | E7: 44931 | F7: 28 | G7: 3.8 | H7: 2023 | I7: Thursday | J7: 10 to 30 mins | K7: 4 | L7: Jan | M7: 1
A8: Call_7290 | B8: C0006 | C8: 48 | D8: R05 | E8: 44932 | F8: 30 | G8: 4.4 | H8: 2023 | I8: Friday | J8: 30 to 60 mins | K8: 4 | L8: Jan | M8: 1
A9: Call_7299 | B9: C0009 | C9: 31 | D9: R04 | E9: 44936 | F9: 123 | G9: 2.9 | H9: 2023 | I9: Tuesday | J9: 30 to 60 mins | K9: 3 | L9: Jan | M9: 1
A10: Call_7301 | B10: C0009 | C10: 80 | D10: R05 | E10: 44936 | F10: 140 | G10: 4.2 | H10: 2023 | I10: Tuesday | J10: 1 to 2 hours | K10: 4 | L10: Jan | M10: 1
A11: Call_7304 | B11: C0006 | C11: 160 | D11: R02 | E11: 44940 | F11: 105 | G11: 5 | H11: 2023 | I11: Saturday | J11: More than 2 hours | K11: 5 | L11: Jan | M11: 1
A12: Call_7305 | B12: C0001 | C12: 105 | D12: R05 | E12: 44941 | F12: 125 | G12: 4.8 | H12: 2023 | I12: Sunday | J12: 1 to 2 hours | K12: 5 | L12: Jan | M12: 1
A13: Call_7306 | B13: C0009 | C13: 75 | D13: R03 | E13: 44941 | F13: 26 | G13: 2.4 | H13: 2023 | I13: Sunday | J13: 1 to 2 hours | K13: 2 | L13: Jan | M13: 1
A14: Call_7310 | B14: C0009 | C14: 106 | D14: R05 | E14: 44943 | F14: 108 | G14: 5 | H14: 2023 | I14: Tuesday | J14: 1 to 2 hours | K14: 5 | L14: Jan | M14: 1
A15: Call_7313 | B15: C0009 | C15: 89 | D15: R05 | E15: 44944 | F15: 155 | G15: 4.1 | H15: 2023 | I15: Wednesday | J15: 1 to 2 hours | K15: 4 | L15: Jan | M15: 1
... A338: Call_8270 | B338: C0009 | C338: 114 | D338: R01 | E338: 45291 | F338: 40 | G338: 3.9 | H338: 2024 | I338: Sunday | J338: 1 to 2 hours | K338: 4 | L338: Dec | M338: 12

Sheet Data
B1: Call Centre Data
B3: Call number | C3: Customer ID | D3: Duration | E3: Representative | F3: Date of Call | G3: Purchase Amount | H3: Satisfaction Rating | I3: FY | J3: Day of week | K3: Duration Bucket | L3: Rating rounded | Q3: Customer ID | R3: Gedner | S3: Age | T3: City
B4: Call_7271 | C4: C0003 | D4: 116 | E4: R05 | F4: 44927 | G4: 128 | H4: 4.9 | I4: =IF(MONTH(calls[[#This Row],[Date of Call]])<=6, YEAR(calls[[#This Row],[Date of Call]]), YEAR(calls[[#This Row],[Date of Call]])+1) -> 2023 | J4: =TEXT(calls[[#This Row],[Date of Call]],"DDDD") -> Sunday | K4: {=_xlfn.IFS(calls[[#This Row],[Duration]]<=10,"Under 10 mins", calls[[#This Row],[Duration]]<=30, "10 to 30 mins", calls[[#This Row],[Duration]]<=60, "30 to 60 mins", calls[[#This Row],[Duration]]<=120, "1 to 2 hours", TRUE, "More than 2 hours")} -> 1 to 2 hours | L4: =ROUND(calls[[#This Row],[Satisfaction Rating]],0) -> 5 | Q4: C0001 | R4: Male | S4: 41 | T4: Columbus
B5: Call_7272 | C5: C0004 | D5: 119 | E5: R05 | F5: 44927 | G5: 135 | H5: 2.9 | I5: =IF(MONTH(calls[[#This Row],[Date of Call]])<=6, YEAR(calls[[#This Row],[Date of Call]]), YEAR(calls[[#This Row],[Date of Call]])+1) -> 2023 | J5: =TEXT(calls[[#This Row],[Date of Call]],"DDDD") -> Sunday | K5: {=_xlfn.IFS(calls[[#This Row],[Duration]]<=10,"Under 10 mins", calls[[#This Row],[Duration]]<=30, "10 to 30 mins", calls[[#This Row],[Duration]]<=60, "30 to 60 mins", calls[[#This Row],[Duration]]<=120, "1 to 2 hours", TRUE, "More than 2 hours")} -> 1 to 2 hours | L5: =ROUND(calls[[#This Row],[Satisfaction Rating]],0) -> 3 | Q5: C0002 | R5: Male | S5: 31 | T5: Cleveland
B6: Call_7273 | C6: C0005 | D6: 68 | E6: R02 | F6: 44927 | G6: 66 | H6: 4.7 | I6: =IF(MONTH(calls[[#This Row],[Date of Call]])<=6, YEAR(calls[[#This Row],[Date of Call]]), YEAR(calls[[#This Row],[Date of Call]])+1) -> 2023 | J6: =TEXT(calls[[#This Row],[Date of Call]],"DDDD") -> Sunday | K6: {=_xlfn.IFS(calls[[#This Row],[Duration]]<=10,"Under 10 mins", calls[[#This Row],[Duration]]<=30, "10 to 30 mins", calls[[#This Row],[Duration]]<=60, "30 to 60 mins", calls[[#This Row],[Duration]]<=120, "1 to 2 hours", TRUE, "More than 2 hours")} -> 1 to 2 hours | L6: =ROUND(calls[[#This Row],[Satisfaction Rating]],0) -> 5 | Q6: C0003 | R6: Male | S6: 26 | T6: Cincinnati
B7: Call_7274 | C7: C0014 | D7: 119 | E7: R02 | F7: 44927 | G7: 22 | H7: 2.9 | I7: =IF(MONTH(calls[[#This Row],[Date of Call]])<=6, YEAR(calls[[#This Row],[Date of Call]]), YEAR(calls[[#This Row],[Date of Call]])+1) -> 2023 | J7: =TEXT(calls[[#This Row],[Date of Call]],"DDDD") -> Sunday | K7: {=_xlfn.IFS(calls[[#This Row],[Duration]]<=10,"Under 10 mins", calls[[#This Row],[Duration]]<=30, "10 to 30 mins", calls[[#This Row],[Duration]]<=60, "30 to 60 mins", calls[[#This Row],[Duration]]<=120, "1 to 2 hours", TRUE, "More than 2 hours")} -> 1 to 2 hours | L7: =ROUND(calls[[#This Row],[Satisfaction Rating]],0) -> 3 | Q7: C0004 | R7: Male | S7: 36 | T7: Cincinnati
B8: Call_7275 | C8: C0011 | D8: 128 | E8: R01 | F8: 44928 | G8: 31 | H8: 2.8 | I8: =IF(MONTH(calls[[#This Row],[Date of Call]])<=6, YEAR(calls[[#This Row],[Date of Call]]), YEAR(calls[[#This Row],[Date of Call]])+1) -> 2023 | J8: =TEXT(calls[[#This Row],[Date of Call]],"DDDD") -> Monday | K8: {=_xlfn.IFS(calls[[#This Row],[Duration]]<=10,"Under 10 mins", calls[[#This Row],[Duration]]<=30, "10 to 30 mins", calls[[#This Row],[Duration]]<=60, "30 to 60 mins", calls[[#This Row],[Duration]]<=120, "1 to 2 hours", TRUE, "More than 2 hours")} -> More than 2 hours | L8: =ROUND(calls[[#This Row],[Satisfaction Rating]],0) -> 3 | Q8: C0005 | R8: Male | S8: 37 | T8: Columbus
B9: Call_7276 | C9: C0011 | D9: 49 | E9: R02 | F9: 44929 | G9: 135 | H9: 4.8 | I9: =IF(MONTH(calls[[#This Row],[Date of Call]])<=6, YEAR(calls[[#This Row],[Date of Call]]), YEAR(calls[[#This Row],[Date of Call]])+1) -> 2023 | J9: =TEXT(calls[[#This Row],[Date of Call]],"DDDD") -> Tuesday | K9: {=_xlfn.IFS(calls[[#This Row],[Duration]]<=10,"Under 10 mins", calls[[#This Row],[Duration]]<=30, "10 to 30 mins", calls[[#This Row],[Duration]]<=60, "30 to 60 mins", calls[[#This Row],[Duration]]<=120, "1 to 2 hours", TRUE, "More than 2 hours")} -> 30 to 60 mins | L9: =ROUND(calls[[#This Row],[Satisfaction Rating]],0) -> 5 | Q9: C0006 | R9: Male | S9: 23 | T9: Columbus
B10: Call_7277 | C10: C0007 | D10: 84 | E10: R05 | F10: 44929 | G10: 60 | H10: 4.7 | I10: =IF(MONTH(calls[[#This Row],[Date of Call]])<=6, YEAR(calls[[#This Row],[Date of Call]]), YEAR(calls[[#This Row],[Date of Call]])+1) -> 2023 | J10: =TEXT(calls[[#This Row],[Date of Call]],"DDDD") -> Tuesday | K10: {=_xlfn.IFS(calls[[#This Row],[Duration]]<=10,"Under 10 mins", calls[[#This Row],[Duration]]<=30, "10 to 30 mins", calls[[#This Row],[Duration]]<=60, "30 to 60 mins", calls[[#This Row],[Duration]]<=120, "1 to 2 hours", TRUE, "More than 2 hours")} -> 1 to 2 hours | L10: =ROUND(calls[[#This Row],[Satisfaction Rating]],0) -> 5 | Q10: C0007 | R10: Female | S10: 22 | T10: Cleveland
B11: Call_7278 | C11: C0003 | D11: 103 | E11: R04 | F11: 44929 | G11: 148 | H11: 4.4 | I11: =IF(MONTH(calls[[#This Row],[Date of Call]])<=6, YEAR(calls[[#This Row],[Date of Call]]), YEAR(calls[[#This Row],[Date of Call]])+1) -> 2023 | J11: =TEXT(calls[[#This Row],[Date of Call]],"DDDD") -> Tuesday | K11: {=_xlfn.IFS(calls[[#This Row],[Duration]]<=10,"Under 10 mins", calls[[#This Row],[Duration]]<=30, "10 to 30 mins", calls[[#This Row],[Duration]]<=60, "30 to 60 mins", calls[[#This Row],[Duration]]<=120, "1 to 2 hours", TRUE, "More than 2 hours")} -> 1 to 2 hours | L11: =ROUND(calls[[#This Row],[Satisfaction Rating]],0) -> 4 | Q11: C0008 | R11: Female | S11: 42 | T11: Cleveland
B12: Call_7279 | C12: C0005 | D12: 31 | E12: R02 | F12: 44929 | G12: 135 | H12: 3.6 | I12: =IF(MONTH(calls[[#This Row],[Date of Call]])<=6, YEAR(calls[[#This Row],[Date of Call]]), YEAR(calls[[#This Row],[Date of Call]])+1) -> 2023 | J12: =TEXT(calls[[#This Row],[Date of Call]],"DDDD") -> Tuesday | K12: {=_xlfn.IFS(calls[[#This Row],[Duration]]<=10,"Under 10 mins", calls[[#This Row],[Duration]]<=30, "10 to 30 mins", calls[[#This Row],[Duration]]<=60, "30 to 60 mins", calls[[#This Row],[Duration]]<=120, "1 to 2 hours", TRUE, "More than 2 hours")} -> 30 to 60 mins | L12: =ROUND(calls[[#This Row],[Satisfaction Rating]],0) -> 4 | Q12: C0009 | R12: Female | S12: 25 | T12: Columbus
B13: Call_7280 | C13: C0010 | D13: 44 | E13: R03 | F13: 44929 | G13: 105 | H13: 2.9 | I13: =IF(MONTH(calls[[#This Row],[Date of Call]])<=6, YEAR(calls[[#This Row],[Date of Call]]), YEAR(calls[[#This Row],[Date of Call]])+1) -> 2023 | J13: =TEXT(calls[[#This Row],[Date of Call]],"DDDD") -> Tuesday | K13: {=_xlfn.IFS(calls[[#This Row],[Duration]]<=10,"Under 10 mins", calls[[#This Row],[Duration]]<=30, "10 to 30 mins", calls[[#This Row],[Duration]]<=60, "30 to 60 mins", calls[[#This Row],[Duration]]<=120, "1 to 2 hours", TRUE, "More than 2 hours")} -> 30 to 60 mins | L13: =ROUND(calls[[#This Row],[Satisfaction Rating]],0) -> 3 | Q13: C0010 | R13: Female | S13: 30 | T13: Cleveland
B14: Call_7281 | C14: C0011 | D14: 102 | E14: R02 | F14: 44929 | G14: 69 | H14: 4.9 | I14: =IF(MONTH(calls[[#This Row],[Date of Call]])<=6, YEAR(calls[[#This Row],[Date of Call]]), YEAR(calls[[#This Row],[Date of Call]])+1) -> 2023 | J14: =TEXT(calls[[#This Row],[Date of Call]],"DDDD") -> Tuesday | K14: {=_xlfn.IFS(calls[[#This Row],[Duration]]<=10,"Under 10 mins", calls[[#This Row],[Duration]]<=30, "10 to 30 mins", calls[[#This Row],[Duration]]<=60, "30 to 60 mins", calls[[#This Row],[Duration]]<=120, "1 to 2 hours", TRUE, "More than 2 hours")} -> 1 to 2 hours | L14: =ROUND(calls[[#This Row],[Satisfaction Rating]],0) -> 5 | Q14: C0011 | R14: Female | S14: 30 | T14: Cincinnati
B15: Call_7282 | C15: C0013 | D15: 135 | E15: R05 | F15: 44929 | G15: 46 | H15: 3.4 | I15: =IF(MONTH(calls[[#This Row],[Date of Call]])<=6, YEAR(calls[[#This Row],[Date of Call]]), YEAR(calls[[#This Row],[Date of Call]])+1) -> 2023 | J15: =TEXT(calls[[#This Row],[Date of Call]],"DDDD") -> Tuesday | K15: {=_xlfn.IFS(calls[[#This Row],[Duration]]<=10,"Under 10 mins", calls[[#This Row],[Duration]]<=30, "10 to 30 mins", calls[[#This Row],[Duration]]<=60, "30 to 60 mins", calls[[#This Row],[Duration]]<=120, "1 to 2 hours", TRUE, "More than 2 hours")} -> More than 2 hours | L15: =ROUND(calls[[#This Row],[Satisfaction Rating]],0) -> 3 | Q15: C0012 | R15: Female | S15: 28 | T15: Cincinnati
... B18: Call_7285 | C18: C0013 | D18: 48 | E18: R01 | F18: 44930 | G18: 68 | H18: 4.9 | I18: =IF(MONTH(calls[[#This Row],[Date of Call]])<=6, YEAR(calls[[#This Row],[Date of Call]]), YEAR(calls[[#This Row],[Date of Call]])+1) -> 2023 | J18: =TEXT(calls[[#This Row],[Date of Call]],"DDDD") -> Wednesday | K18: {=_xlfn.IFS(calls[[#This Row],[Duration]]<=10,"Under 10 mins", calls[[#This Row],[Duration]]<=30, "10 to 30 mins", calls[[#This Row],[Duration]]<=60, "30 to 60 mins", calls[[#This Row],[Duration]]<=120, "1 to 2 hours", TRUE, "More than 2 hours")} -> 30 to 60 mins | L18: =ROUND(calls[[#This Row],[Satisfaction Rating]],0) -> 5 | Q18: C0015 | R18: Female | S18: 43 | T18: Cleveland
B19: Call_7286 | C19: C0010 | D19: 176 | E19: R05 | F19: 44931 | G19: 24 | H19: 4.8 | I19: =IF(MONTH(calls[[#This Row],[Date of Call]])<=6, YEAR(calls[[#This Row],[Date of Call]]), YEAR(calls[[#This Row],[Date of Call]])+1) -> 2023 | J19: =TEXT(calls[[#This Row],[Date of Call]],"DDDD") -> Thursday | K19: {=_xlfn.IFS(calls[[#This Row],[Duration]]<=10,"Under 10 mins", calls[[#This Row],[Duration]]<=30, "10 to 30 mins", calls[[#This Row],[Duration]]<=60, "30 to 60 mins", calls[[#This Row],[Duration]]<=120, "1 to 2 hours", TRUE, "More than 2 hours")} -> More than 2 hours | L19: =ROUND(calls[[#This Row],[Satisfaction Rating]],0) -> 5
B20: Call_7287 | C20: C0010 | D20: 99 | E20: R01 | F20: 44931 | G20: 195 | H20: 3.9 | I20: =IF(MONTH(calls[[#This Row],[Date of Call]])<=6, YEAR(calls[[#This Row],[Date of Call]]), YEAR(calls[[#This Row],[Date of Call]])+1) -> 2023 | J20: =TEXT(calls[[#This Row],[Date of Call]],"DDDD") -> Thursday | K20: {=_xlfn.IFS(calls[[#This Row],[Duration]]<=10,"Under 10 mins", calls[[#This Row],[Duration]]<=30, "10 to 30 mins", calls[[#This Row],[Duration]]<=60, "30 to 60 mins", calls[[#This Row],[Duration]]<=120, "1 to 2 hours", TRUE, "More than 2 hours")} -> 1 to 2 hours | L20: =ROUND(calls[[#This Row],[Satisfaction Rating]],0) -> 4
B21: Call_7288 | C21: C0009 | D21: 28 | E21: R03 | F21: 44931 | G21: 28 | H21: 3.8 | I21: =IF(MONTH(calls[[#This Row],[Date of Call]])<=6, YEAR(calls[[#This Row],[Date of Call]]), YEAR(calls[[#This Row],[Date of Call]])+1) -> 2023 | J21: =TEXT(calls[[#This Row],[Date of Call]],"DDDD") -> Thursday | K21: {=_xlfn.IFS(calls[[#This Row],[Duration]]<=10,"Under 10 mins", calls[[#This Row],[Duration]]<=30, "10 to 30 mins", calls[[#This Row],[Duration]]<=60, "30 to 60 mins", calls[[#This Row],[Duration]]<=120, "1 to 2 hours", TRUE, "More than 2 hours")} -> 10 to 30 mins | L21: =ROUND(calls[[#This Row],[Satisfaction Rating]],0) -> 4
B22: Call_7289 | C22: C0007 | D22: 54 | E22: R02 | F22: 44931 | G22: 170 | H22: 4.3 | I22: =IF(MONTH(calls[[#This Row],[Date of Call]])<=6, YEAR(calls[[#This Row],[Date of Call]]), YEAR(calls[[#This Row],[Date of Call]])+1) -> 2023 | J22: =TEXT(calls[[#This Row],[Date of Call]],"DDDD") -> Thursday | K22: {=_xlfn.IFS(calls[[#This Row],[Duration]]<=10,"Under 10 mins", calls[[#This Row],[Duration]]<=30, "10 to 30 mins", calls[[#This Row],[Duration]]<=60, "30 to 60 mins", calls[[#This Row],[Duration]]<=120, "1 to 2 hours", TRUE, "More than 2 hours")} -> 30 to 60 mins | L22: =ROUND(calls[[#This Row],[Satisfaction Rating]],0) -> 4
B23: Call_7290 | C23: C0006 | D23: 48 | E23: R05 | F23: 44932 | G23: 30 | H23: 4.4 | I23: =IF(MONTH(calls[[#This Row],[Date of Call]])<=6, YEAR(calls[[#This Row],[Date of Call]]), YEAR(calls[[#This Row],[Date of Call]])+1) -> 2023 | J23: =TEXT(calls[[#This Row],[Date of Call]],"DDDD") -> Friday | K23: {=_xlfn.IFS(calls[[#This Row],[Duration]]<=10,"Under 10 mins", calls[[#This Row],[Duration]]<=30, "10 to 30 mins", calls[[#This Row],[Duration]]<=60, "30 to 60 mins", calls[[#This Row],[Duration]]<=120, "1 to 2 hours", TRUE, "More than 2 hours")} -> 30 to 60 mins | L23: =ROUND(calls[[#This Row],[Satisfaction Rating]],0) -> 4
B24: Call_7291 | C24: C0004 | D24: 128 | E24: R05 | F24: 44932 | G24: 72 | H24: 5 | I24: =IF(MONTH(calls[[#This Row],[Date of Call]])<=6, YEAR(calls[[#This Row],[Date of Call]]), YEAR(calls[[#This Row],[Date of Call]])+1) -> 2023 | J24: =TEXT(calls[[#This Row],[Date of Call]],"DDDD") -> Friday | K24: {=_xlfn.IFS(calls[[#This Row],[Duration]]<=10,"Under 10 mins", calls[[#This Row],[Duration]]<=30, "10 to 30 mins", calls[[#This Row],[Duration]]<=60, "30 to 60 mins", calls[[#This Row],[Duration]]<=120, "1 to 2 hours", TRUE, "More than 2 hours")} -> More than 2 hours | L24: =ROUND(calls[[#This Row],[Satisfaction Rating]],0) -> 5
B25: Call_7292 | C25: C0004 | D25: 38 | E25: R04 | F25: 44933 | G25: 92 | H25: 4.9 | I25: =IF(MONTH(calls[[#This Row],[Date of Call]])<=6, YEAR(calls[[#This Row],[Date of Call]]), YEAR(calls[[#This Row],[Date of Call]])+1) -> 2023 | J25: =TEXT(calls[[#This Row],[Date of Call]],"DDDD") -> Saturday | K25: {=_xlfn.IFS(calls[[#This Row],[Duration]]<=10,"Under 10 mins", calls[[#This Row],[Duration]]<=30, "10 to 30 mins", calls[[#This Row],[Duration]]<=60, "30 to 60 mins", calls[[#This Row],[Duration]]<=120, "1 to 2 hours", TRUE, "More than 2 hours")} -> 30 to 60 mins | L25: =ROUND(calls[[#This Row],[Satisfaction Rating]],0) -> 5
B26: Call_7293 | C26: C0003 | D26: 67 | E26: R04 | F26: 44934 | G26: 165 | H26: 4.5 | I26: =IF(MONTH(calls[[#This Row],[Date of Call]])<=6, YEAR(calls[[#This Row],[Date of Call]]), YEAR(calls[[#This Row],[Date of Call]])+1) -> 2023 | J26: =TEXT(calls[[#This Row],[Date of Call]],"DDDD") -> Sunday | K26: {=_xlfn.IFS(calls[[#This Row],[Duration]]<=10,"Under 10 mins", calls[[#This Row],[Duration]]<=30, "10 to 30 mins", calls[[#This Row],[Duration]]<=60, "30 to 60 mins", calls[[#This Row],[Duration]]<=120, "1 to 2 hours", TRUE, "More than 2 hours")} -> 1 to 2 hours | L26: =ROUND(calls[[#This Row],[Satisfaction Rating]],0) -> 5
B27: Call_7294 | C27: C0015 | D27: 58 | E27: R02 | F27: 44934 | G27: 140 | H27: 2.1 | I27: =IF(MONTH(calls[[#This Row],[Date of Call]])<=6, YEAR(calls[[#This Row],[Date of Call]]), YEAR(calls[[#This Row],[Date of Call]])+1) -> 2023 | J27: =TEXT(calls[[#This Row],[Date of Call]],"DDDD") -> Sunday | K27: {=_xlfn.IFS(calls[[#This Row],[Duration]]<=10,"Under 10 mins", calls[[#This Row],[Duration]]<=30, "10 to 30 mins", calls[[#This Row],[Duration]]<=60, "30 to 60 mins", calls[[#This Row],[Duration]]<=120, "1 to 2 hours", TRUE, "More than 2 hours")} -> 30 to 60 mins | L27: =ROUND(calls[[#This Row],[Satisfaction Rating]],0) -> 2
B28: Call_7295 | C28: C0010 | D28: 54 | E28: R01 | F28: 44934 | G28: 111 | H28: 3.3 | I28: =IF(MONTH(calls[[#This Row],[Date of Call]])<=6, YEAR(calls[[#This Row],[Date of Call]]), YEAR(calls[[#This Row],[Date of Call]])+1) -> 2023 | J28: =TEXT(calls[[#This Row],[Date of Call]],"DDDD") -> Sunday | K28: {=_xlfn.IFS(calls[[#This Row],[Duration]]<=10,"Under 10 mins", calls[[#This Row],[Duration]]<=30, "10 to 30 mins", calls[[#This Row],[Duration]]<=60, "30 to 60 mins", calls[[#This Row],[Duration]]<=120, "1 to 2 hours", TRUE, "More than 2 hours")} -> 30 to 60 mins | L28: =ROUND(calls[[#This Row],[Satisfaction Rating]],0) -> 3
B29: Call_7296 | C29: C0012 | D29: 28 | E29: R05 | F29: 44935 | G29: 63 | H29: 4.1 | I29: =IF(MONTH(calls[[#This Row],[Date of Call]])<=6, YEAR(calls[[#This Row],[Date of Call]]), YEAR(calls[[#This Row],[Date of Call]])+1) -> 2023 | J29: =TEXT(calls[[#This Row],[Date of Call]],"DDDD") -> Monday | K29: {=_xlfn.IFS(calls[[#This Row],[Duration]]<=10,"Under 10 mins", calls[[#This Row],[Duration]]<=30, "10 to 30 mins", calls[[#This Row],[Duration]]<=60, "30 to 60 mins", calls[[#This Row],[Duration]]<=120, "1 to 2 hours", TRUE, "More than 2 hours")} -> 10 to 30 mins | L29: =ROUND(calls[[#This Row],[Satisfaction Rating]],0) -> 4
B30: Call_7297 | C30: C0002 | D30: 73 | E30: R05 | F30: 44935 | G30: 80 | H30: 4.2 | I30: =IF(MONTH(calls[[#This Row],[Date of Call]])<=6, YEAR(calls[[#This Row],[Date of Call]]), YEAR(calls[[#This Row],[Date of Call]])+1) -> 2023 | J30: =TEXT(calls[[#This Row],[Date of Call]],"DDDD") -> Monday | K30: {=_xlfn.IFS(calls[[#This Row],[Duration]]<=10,"Under 10 mins", calls[[#This Row],[Duration]]<=30, "10 to 30 mins", calls[[#This Row],[Duration]]<=60, "30 to 60 mins", calls[[#This Row],[Duration]]<=120, "1 to 2 hours", TRUE, "More than 2 hours")} -> 1 to 2 hours | L30: =ROUND(calls[[#This Row],[Satisfaction Rating]],0) -> 4
... B1003: Call_8270 | C1003: C0009 | D1003: 114 | E1003: R01 | F1003: 45291 | G1003: 40 | H1003: 3.9 | I1003: =IF(MONTH(calls[[#This Row],[Date of Call]])<=6, YEAR(calls[[#This Row],[Date of Call]]), YEAR(calls[[#This Row],[Date of Call]])+1) -> 2024 | J1003: =TEXT(calls[[#This Row],[Date of Call]],"DDDD") -> Sunday | K1003: {=_xlfn.IFS(calls[[#This Row],[Duration]]<=10,"Under 10 mins", calls[[#This Row],[Duration]]<=30, "10 to 30 mins", calls[[#This Row],[Duration]]<=60, "30 to 60 mins", calls[[#This Row],[Duration]]<=120, "1 to 2 hours", TRUE, "More than 2 hours")} -> 1 to 2 hours | L1003: =ROUND(calls[[#This Row],[Satisfaction Rating]],0) -> 4

Sheet Pivot Tables
A3: call count | B3: Total Amount | C3: Total Duration | D3: Average Rating | E3: 5*rating
A4: 1000 | B4: 96623 | C4: 89850 | D4: 3.8854 | E4: 307
A13: call count | B13: Total Amount | C13: Total Duration | D13: Average Rating | E13: 5*rating
A14: 189 | B14: 18415 | C14: 16834 | D14: 3.9227513 | E14: 60
A20: Row Labels | B20: call count | C20: call count2
A21: Jan | B21: 16 | C21: 16
A22: Feb | B22: 14 | C22: 14
A23: Mar | B23: 26 | C23: 26
A24: Apr | B24: 29 | C24: 29
A25: May | B25: 17 | C25: 17 | L25: Row Labels | M25: call count
A26: Jun | B26: 15 | C26: 15 | L26: Sunday | M26: 36
A27: Jul | B27: 15 | C27: 15 | L27: Monday | M27: 30
A28: Aug | B28: 7 | C28: 7 | L28: Tuesday | M28: 13
A29: Sep | B29: 11 | C29: 11 | L29: Wednesday | M29: 23
A30: Oct | B30: 24 | C30: 24 | L30: Thursday | M30: 23
A31: Nov | B31: 9 | C31: 9 | L31: Friday | M31: 24
A32: Dec | B32: 6 | C32: 6 | L32: Saturday | M32: 40
A33: Grand Total | B33: 189 | C33: 189 | L33: Grand Total | M33: 189
E34: Row Labels | F34: call count
E35: 1 | F35: 1
E36: 2 | F36: 9
E37: 3 | F37: 31
E38: 4 | F38: 88
E39: 5 | F39: 60
E40: Grand Total | F40: 189
I41: Total Amount | J41: Column Labels
I42: Row Labels | J42: R01 | K42: R02 | L42: R03 | M42: R04 | N42: R05 | O42: Grand Total
I43: Cincinnati | S43: Cincinnati
I44: C0003 | J44: 891 | K44: 1332 | L44: 1282 | M44: 739 | N44: 560 | O44: 4804 | S44: C0003 | T44: 891 | U44: 1332 | V44: 1282 | W44: 739 | X44: 560 | Y44: 4804
I45: C0004 | J45: 1991 | K45: 1886 | L45: 1206 | M45: 884 | N45: 1722 | O45: 7689 | S45: C0004 | T45: 1991 | U45: 1886 | V45: 1206 | W45: 884 | X45: 1722 | Y45: 7689
I46: C0011 | J46: 1163 | K46: 1180 | L46: 1616 | M46: 1043 | N46: 1747 | O46: 6749 | S46: C0011 | T46: 1163 | U46: 1180 | V46: 1616 | W46: 1043 | X46: 1747 | Y46: 6749
I47: C0012 | J47: 1438 | K47: 1616 | L47: 866 | M47: 829 | N47: 2070 | O47: 6819 | S47: C0012 | T47: 1438 | U47: 1616 | V47: 866 | W47: 829 | X47: 2070 | Y47: 6819
I48: Cleveland | S48: Cleveland
I49: C0002 | J49: 1233 | K49: 223 | L49: 1680 | M49: 990 | N49: 1508 | O49: 5634 | S49: C0002 | T49: 1233 | U49: 223 | V49: 1680 | W49: 990 | X49: 1508 | Y49: 5634
I50: C0007 | J50: 1598 | K50: 1907 | L50: 869 | M50: 1426 | N50: 1416 | O50: 7216 | S50: C0007 | T50: 1598 | U50: 1907 | V50: 869 | W50: 1426 | X50: 1416 | Y50: 7216
I51: C0008 | J51: 900 | K51: 1016 | L51: 960 | M51: 940 | N51: 1193 | O51: 5009 | S51: C0008 | T51: 900 | U51: 1016 | V51: 960 | W51: 940 | X51: 1193 | Y51: 5009
I52: C0010 | J52: 900 | K52: 1470 | L52: 1617 | M52: 1314 | N52: 941 | O52: 6242 | S52: C0010 | T52: 900 | U52: 1470 | V52: 1617 | W52: 1314 | X52: 941 | Y52: 6242
I53: C0013 | J53: 1255 | K53: 516 | L53: 1874 | M53: 1863 | N53: 1722 | O53: 7230 | S53: C0013 | T53: 1255 | U53: 516 | V53: 1874 | W53: 1863 | X53: 1722 | Y53: 7230
I54: C0015 | J54: 1138 | K54: 1898 | L54: 1482 | M54: 846 | N54: 1154 | O54: 6518 | S54: C0015 | T54: 1138 | U54: 1898 | V54: 1482 | W54: 846 | X54: 1154 | Y54: 6518
I55: Columbus | S55: Columbus
...

Sheet Call-Center-Report-Dashboard
I1: CALL CENTER REPORT 2023
AA22: R01 | AB22: R02 | AC22: R03 | AD22: R04 | AE22: R05 | AF22: Grand Total
Z23: ='Pivot Tables'!I43 -> Cincinnati
Z24: ='Pivot Tables'!I44 -> C0003 | AA24: ='Pivot Tables'!J44 -> 891 | AB24: ='Pivot Tables'!K44 -> 1332 | AC24: ='Pivot Tables'!L44 -> 1282 | AD24: ='Pivot Tables'!M44 -> 739 | AE24: ='Pivot Tables'!N44 -> 560 | AF24: ='Pivot Tables'!O44 -> 4804
Z25: ='Pivot Tables'!I45 -> C0004 | AA25: ='Pivot Tables'!J45 -> 1991 | AB25: ='Pivot Tables'!K45 -> 1886 | AC25: ='Pivot Tables'!L45 -> 1206 | AD25: ='Pivot Tables'!M45 -> 884 | AE25: ='Pivot Tables'!N45 -> 1722 | AF25: ='Pivot Tables'!O45 -> 7689
Z26: ='Pivot Tables'!I46 -> C0011 | AA26: ='Pivot Tables'!J46 -> 1163 | AB26: ='Pivot Tables'!K46 -> 1180 | AC26: ='Pivot Tables'!L46 -> 1616 | AD26: ='Pivot Tables'!M46 -> 1043 | AE26: ='Pivot Tables'!N46 -> 1747 | AF26: ='Pivot Tables'!O46 -> 6749
Z27: ='Pivot Tables'!I47 -> C0012 | AA27: ='Pivot Tables'!J47 -> 1438 | AB27: ='Pivot Tables'!K47 -> 1616 | AC27: ='Pivot Tables'!L47 -> 866 | AD27: ='Pivot Tables'!M47 -> 829 | AE27: ='Pivot Tables'!N47 -> 2070 | AF27: ='Pivot Tables'!O47 -> 6819
Z28: ='Pivot Tables'!I48 -> Cleveland
Z29: ='Pivot Tables'!I49 -> C0002 | AA29: ='Pivot Tables'!J49 -> 1233 | AB29: ='Pivot Tables'!K49 -> 223 | AC29: ='Pivot Tables'!L49 -> 1680 | AD29: ='Pivot Tables'!M49 -> 990 | AE29: ='Pivot Tables'!N49 -> 1508 | AF29: ='Pivot Tables'!O49 -> 5634
Z30: ='Pivot Tables'!I50 -> C0007 | AA30: ='Pivot Tables'!J50 -> 1598 | AB30: ='Pivot Tables'!K50 -> 1907 | AC30: ='Pivot Tables'!L50 -> 869 | AD30: ='Pivot Tables'!M50 -> 1426 | AE30: ='Pivot Tables'!N50 -> 1416 | AF30: ='Pivot Tables'!O50 -> 7216
Z31: ='Pivot Tables'!I51 -> C0008 | AA31: ='Pivot Tables'!J51 -> 900 | AB31: ='Pivot Tables'!K51 -> 1016 | AC31: ='Pivot Tables'!L51 -> 960 | AD31: ='Pivot Tables'!M51 -> 940 | AE31: ='Pivot Tables'!N51 -> 1193 | AF31: ='Pivot Tables'!O51 -> 5009
T32: ="Representative Info:"&'Pivot Tables'!B109 -> Representative Info:R01 | Z32: ='Pivot Tables'!I52 -> C0010 | AA32: ='Pivot Tables'!J52 -> 900 | AB32: ='Pivot Tables'!K52 -> 1470 | AC32: ='Pivot Tables'!L52 -> 1617 | AD32: ='Pivot Tables'!M52 -> 1314 | AE32: ='Pivot Tables'!N52 -> 941 | AF32: ='Pivot Tables'!O52 -> 6242
T33: ='Pivot Tables'!C130 -> %of calls:19% | Z33: ='Pivot Tables'!I53 -> C0013 | AA33: ='Pivot Tables'!J53 -> 1255 | AB33: ='Pivot Tables'!K53 -> 516 | AC33: ='Pivot Tables'!L53 -> 1874 | AD33: ='Pivot Tables'!M53 -> 1863 | AE33: ='Pivot Tables'!N53 -> 1722 | AF33: ='Pivot Tables'!O53 -> 7230
T34: ='Pivot Tables'!C131 -> %Call Rank: 4 | Z34: ='Pivot Tables'!I54 -> C0015 | AA34: ='Pivot Tables'!J54 -> 1138 | AB34: ='Pivot Tables'!K54 -> 1898 | AC34: ='Pivot Tables'!L54 -> 1482 | AD34: ='Pivot Tables'!M54 -> 846 | AE34: ='Pivot Tables'!N54 -> 1154 | AF34: ='Pivot Tables'!O54 -> 6518
T35: ='Pivot Tables'!C132 -> Amount Rank:4 | Z35: ='Pivot Tables'!I55 -> Columbus
Z36: ='Pivot Tables'!I56 -> C0001 | AA36: ='Pivot Tables'!J56 -> 1655 | AB36: ='Pivot Tables'!K56 -> 805 | AC36: ='Pivot Tables'!L56 -> 2263 | AD36: ='Pivot Tables'!M56 -> 987 | AE36: ='Pivot Tables'!N56 -> 1075 | AF36: ='Pivot Tables'!O56 -> 6785
Z37: ='Pivot Tables'!I57 -> C0005 | AA37: ='Pivot Tables'!J57 -> 1104 | AB37: ='Pivot Tables'!K57 -> 2280 | AC37: ='Pivot Tables'!L57 -> 1445 | AD37: ='Pivot Tables'!M57 -> 1722 | AE37: ='Pivot Tables'!N57 -> 1196 | AF37: ='Pivot Tables'!O57 -> 7747
Z38: ='Pivot Tables'!I58 -> C0006 | AA38: ='Pivot Tables'!J58 -> 372 | AB38: ='Pivot Tables'!K58 -> 1818 | AC38: ='Pivot Tables'!L58 -> 1346 | AD38: ='Pivot Tables'!M58 -> 1156 | AE38: ='Pivot Tables'!N58 -> 1484 | AF38: ='Pivot Tables'!O58 -> 6176
Z39: ='Pivot Tables'!I59 -> C0009 | AA39: ='Pivot Tables'!J59 -> 1415 | AB39: ='Pivot Tables'!K59 -> 1271 | AC39: ='Pivot Tables'!L59 -> 1214 | AD39: ='Pivot Tables'!M59 -> 1135 | AE39: ='Pivot Tables'!N59 -> 1566 | AF39: ='Pivot Tables'!O59 -> 6601
Z40: ='Pivot Tables'!I60 -> C0014 | AA40: ='Pivot Tables'!J60 -> 1362 | AB40: ='Pivot Tables'!K60 -> 1363 | AC40: ='Pivot Tables'!L60 -> 1152 | AD40: ='Pivot Tables'!M60 -> 777 | AE40: ='Pivot Tables'!N60 -> 750 | AF40: ='Pivot Tables'!O60 -> 5404

Sheet Assets
E2: Rep ID | F2: Rep Image
E3: R01 | F3: #VALUE!
E4: R02 | F4: #VALUE!
E5: R03 | F5: #VALUE!
E6: R04 | F6: #VALUE!
E7: R05 | F7: #VALUE!
K12: =
